[2025-03-09T17:45:32.067+0000] {processor.py:186} INFO - Started process (PID=76) to work on /opt/airflow/dags/extra_dados_climaticos.py
[2025-03-09T17:45:32.070+0000] {processor.py:914} INFO - Processing file /opt/airflow/dags/extra_dados_climaticos.py for tasks to queue
[2025-03-09T17:45:32.074+0000] {logging_mixin.py:190} INFO - [2025-03-09T17:45:32.074+0000] {dagbag.py:588} INFO - Filling up the DagBag from /opt/airflow/dags/extra_dados_climaticos.py
[2025-03-09T17:45:32.095+0000] {logging_mixin.py:190} INFO - [2025-03-09T17:45:32.091+0000] {dagbag.py:387} ERROR - Failed to import: /opt/airflow/dags/extra_dados_climaticos.py
Traceback (most recent call last):
  File "/home/airflow/.local/lib/python3.12/site-packages/airflow/models/dagbag.py", line 383, in parse
    loader.exec_module(new_module)
  File "<frozen importlib._bootstrap_external>", line 995, in exec_module
  File "<frozen importlib._bootstrap_external>", line 1133, in get_code
  File "<frozen importlib._bootstrap_external>", line 1063, in source_to_code
  File "<frozen importlib._bootstrap>", line 488, in _call_with_frames_removed
  File "/opt/airflow/dags/extra_dados_climaticos.py", line 41
    tarefa_1 >> tarefa_2ile_path + 'condicoes.csv')
                                                  ^
SyntaxError: unmatched ')'
[2025-03-09T17:45:32.096+0000] {processor.py:927} WARNING - No viable dags retrieved from /opt/airflow/dags/extra_dados_climaticos.py
[2025-03-09T17:45:32.126+0000] {processor.py:208} INFO - Processing /opt/airflow/dags/extra_dados_climaticos.py took 0.068 seconds
[2025-03-09T17:46:02.736+0000] {processor.py:186} INFO - Started process (PID=142) to work on /opt/airflow/dags/extra_dados_climaticos.py
[2025-03-09T17:46:02.737+0000] {processor.py:914} INFO - Processing file /opt/airflow/dags/extra_dados_climaticos.py for tasks to queue
[2025-03-09T17:46:02.740+0000] {logging_mixin.py:190} INFO - [2025-03-09T17:46:02.740+0000] {dagbag.py:588} INFO - Filling up the DagBag from /opt/airflow/dags/extra_dados_climaticos.py
[2025-03-09T17:46:02.756+0000] {logging_mixin.py:190} INFO - [2025-03-09T17:46:02.755+0000] {dagbag.py:387} ERROR - Failed to import: /opt/airflow/dags/extra_dados_climaticos.py
Traceback (most recent call last):
  File "/home/airflow/.local/lib/python3.12/site-packages/airflow/models/dagbag.py", line 383, in parse
    loader.exec_module(new_module)
  File "<frozen importlib._bootstrap_external>", line 995, in exec_module
  File "<frozen importlib._bootstrap_external>", line 1133, in get_code
  File "<frozen importlib._bootstrap_external>", line 1063, in source_to_code
  File "<frozen importlib._bootstrap>", line 488, in _call_with_frames_removed
  File "/opt/airflow/dags/extra_dados_climaticos.py", line 41
    tarefa_1 >> tarefa_2ile_path + 'condicoes.csv')
                                                  ^
SyntaxError: unmatched ')'
[2025-03-09T17:46:02.757+0000] {processor.py:927} WARNING - No viable dags retrieved from /opt/airflow/dags/extra_dados_climaticos.py
[2025-03-09T17:46:02.786+0000] {processor.py:208} INFO - Processing /opt/airflow/dags/extra_dados_climaticos.py took 0.057 seconds
[2025-03-09T17:46:33.064+0000] {processor.py:186} INFO - Started process (PID=208) to work on /opt/airflow/dags/extra_dados_climaticos.py
[2025-03-09T17:46:33.065+0000] {processor.py:914} INFO - Processing file /opt/airflow/dags/extra_dados_climaticos.py for tasks to queue
[2025-03-09T17:46:33.068+0000] {logging_mixin.py:190} INFO - [2025-03-09T17:46:33.068+0000] {dagbag.py:588} INFO - Filling up the DagBag from /opt/airflow/dags/extra_dados_climaticos.py
[2025-03-09T17:46:33.081+0000] {logging_mixin.py:190} INFO - [2025-03-09T17:46:33.080+0000] {dagbag.py:387} ERROR - Failed to import: /opt/airflow/dags/extra_dados_climaticos.py
Traceback (most recent call last):
  File "/home/airflow/.local/lib/python3.12/site-packages/airflow/models/dagbag.py", line 383, in parse
    loader.exec_module(new_module)
  File "<frozen importlib._bootstrap_external>", line 995, in exec_module
  File "<frozen importlib._bootstrap_external>", line 1133, in get_code
  File "<frozen importlib._bootstrap_external>", line 1063, in source_to_code
  File "<frozen importlib._bootstrap>", line 488, in _call_with_frames_removed
  File "/opt/airflow/dags/extra_dados_climaticos.py", line 41
    tarefa_1 >> tarefa_2ile_path + 'condicoes.csv')
                                                  ^
SyntaxError: unmatched ')'
[2025-03-09T17:46:33.082+0000] {processor.py:927} WARNING - No viable dags retrieved from /opt/airflow/dags/extra_dados_climaticos.py
[2025-03-09T17:46:33.103+0000] {processor.py:208} INFO - Processing /opt/airflow/dags/extra_dados_climaticos.py took 0.048 seconds
[2025-03-09T17:47:03.176+0000] {processor.py:186} INFO - Started process (PID=266) to work on /opt/airflow/dags/extra_dados_climaticos.py
[2025-03-09T17:47:03.177+0000] {processor.py:914} INFO - Processing file /opt/airflow/dags/extra_dados_climaticos.py for tasks to queue
[2025-03-09T17:47:03.180+0000] {logging_mixin.py:190} INFO - [2025-03-09T17:47:03.180+0000] {dagbag.py:588} INFO - Filling up the DagBag from /opt/airflow/dags/extra_dados_climaticos.py
[2025-03-09T17:47:03.195+0000] {logging_mixin.py:190} INFO - [2025-03-09T17:47:03.194+0000] {dagbag.py:387} ERROR - Failed to import: /opt/airflow/dags/extra_dados_climaticos.py
Traceback (most recent call last):
  File "/home/airflow/.local/lib/python3.12/site-packages/airflow/models/dagbag.py", line 383, in parse
    loader.exec_module(new_module)
  File "<frozen importlib._bootstrap_external>", line 995, in exec_module
  File "<frozen importlib._bootstrap_external>", line 1133, in get_code
  File "<frozen importlib._bootstrap_external>", line 1063, in source_to_code
  File "<frozen importlib._bootstrap>", line 488, in _call_with_frames_removed
  File "/opt/airflow/dags/extra_dados_climaticos.py", line 41
    tarefa_1 >> tarefa_2ile_path + 'condicoes.csv')
                                                  ^
SyntaxError: unmatched ')'
[2025-03-09T17:47:03.196+0000] {processor.py:927} WARNING - No viable dags retrieved from /opt/airflow/dags/extra_dados_climaticos.py
[2025-03-09T17:47:03.220+0000] {processor.py:208} INFO - Processing /opt/airflow/dags/extra_dados_climaticos.py took 0.049 seconds
[2025-03-09T17:47:33.708+0000] {processor.py:186} INFO - Started process (PID=332) to work on /opt/airflow/dags/extra_dados_climaticos.py
[2025-03-09T17:47:33.709+0000] {processor.py:914} INFO - Processing file /opt/airflow/dags/extra_dados_climaticos.py for tasks to queue
[2025-03-09T17:47:33.713+0000] {logging_mixin.py:190} INFO - [2025-03-09T17:47:33.713+0000] {dagbag.py:588} INFO - Filling up the DagBag from /opt/airflow/dags/extra_dados_climaticos.py
[2025-03-09T17:47:33.730+0000] {logging_mixin.py:190} INFO - [2025-03-09T17:47:33.729+0000] {dagbag.py:387} ERROR - Failed to import: /opt/airflow/dags/extra_dados_climaticos.py
Traceback (most recent call last):
  File "/home/airflow/.local/lib/python3.12/site-packages/airflow/models/dagbag.py", line 383, in parse
    loader.exec_module(new_module)
  File "<frozen importlib._bootstrap_external>", line 995, in exec_module
  File "<frozen importlib._bootstrap_external>", line 1133, in get_code
  File "<frozen importlib._bootstrap_external>", line 1063, in source_to_code
  File "<frozen importlib._bootstrap>", line 488, in _call_with_frames_removed
  File "/opt/airflow/dags/extra_dados_climaticos.py", line 41
    tarefa_1 >> tarefa_2ile_path + 'condicoes.csv')
                                                  ^
SyntaxError: unmatched ')'
[2025-03-09T17:47:33.731+0000] {processor.py:927} WARNING - No viable dags retrieved from /opt/airflow/dags/extra_dados_climaticos.py
[2025-03-09T17:47:33.757+0000] {processor.py:208} INFO - Processing /opt/airflow/dags/extra_dados_climaticos.py took 0.058 seconds
[2025-03-09T17:48:04.505+0000] {processor.py:186} INFO - Started process (PID=397) to work on /opt/airflow/dags/extra_dados_climaticos.py
[2025-03-09T17:48:04.516+0000] {processor.py:914} INFO - Processing file /opt/airflow/dags/extra_dados_climaticos.py for tasks to queue
[2025-03-09T17:48:04.519+0000] {logging_mixin.py:190} INFO - [2025-03-09T17:48:04.519+0000] {dagbag.py:588} INFO - Filling up the DagBag from /opt/airflow/dags/extra_dados_climaticos.py
[2025-03-09T17:48:04.576+0000] {logging_mixin.py:190} INFO - [2025-03-09T17:48:04.575+0000] {dagbag.py:387} ERROR - Failed to import: /opt/airflow/dags/extra_dados_climaticos.py
Traceback (most recent call last):
  File "/home/airflow/.local/lib/python3.12/site-packages/airflow/models/dagbag.py", line 383, in parse
    loader.exec_module(new_module)
  File "<frozen importlib._bootstrap_external>", line 995, in exec_module
  File "<frozen importlib._bootstrap_external>", line 1133, in get_code
  File "<frozen importlib._bootstrap_external>", line 1063, in source_to_code
  File "<frozen importlib._bootstrap>", line 488, in _call_with_frames_removed
  File "/opt/airflow/dags/extra_dados_climaticos.py", line 41
    tarefa_1 >> tarefa_2ile_path + 'condicoes.csv')
                                                  ^
SyntaxError: unmatched ')'
[2025-03-09T17:48:04.579+0000] {processor.py:927} WARNING - No viable dags retrieved from /opt/airflow/dags/extra_dados_climaticos.py
[2025-03-09T17:48:04.631+0000] {processor.py:208} INFO - Processing /opt/airflow/dags/extra_dados_climaticos.py took 0.131 seconds
[2025-03-09T17:48:35.016+0000] {processor.py:186} INFO - Started process (PID=462) to work on /opt/airflow/dags/extra_dados_climaticos.py
[2025-03-09T17:48:35.017+0000] {processor.py:914} INFO - Processing file /opt/airflow/dags/extra_dados_climaticos.py for tasks to queue
[2025-03-09T17:48:35.020+0000] {logging_mixin.py:190} INFO - [2025-03-09T17:48:35.020+0000] {dagbag.py:588} INFO - Filling up the DagBag from /opt/airflow/dags/extra_dados_climaticos.py
[2025-03-09T17:48:35.037+0000] {logging_mixin.py:190} INFO - [2025-03-09T17:48:35.035+0000] {dagbag.py:387} ERROR - Failed to import: /opt/airflow/dags/extra_dados_climaticos.py
Traceback (most recent call last):
  File "/home/airflow/.local/lib/python3.12/site-packages/airflow/models/dagbag.py", line 383, in parse
    loader.exec_module(new_module)
  File "<frozen importlib._bootstrap_external>", line 995, in exec_module
  File "<frozen importlib._bootstrap_external>", line 1133, in get_code
  File "<frozen importlib._bootstrap_external>", line 1063, in source_to_code
  File "<frozen importlib._bootstrap>", line 488, in _call_with_frames_removed
  File "/opt/airflow/dags/extra_dados_climaticos.py", line 41
    tarefa_1 >> tarefa_2ile_path + 'condicoes.csv')
                                                  ^
SyntaxError: unmatched ')'
[2025-03-09T17:48:35.038+0000] {processor.py:927} WARNING - No viable dags retrieved from /opt/airflow/dags/extra_dados_climaticos.py
[2025-03-09T17:48:35.064+0000] {processor.py:208} INFO - Processing /opt/airflow/dags/extra_dados_climaticos.py took 0.055 seconds
[2025-03-09T17:49:05.386+0000] {processor.py:186} INFO - Started process (PID=527) to work on /opt/airflow/dags/extra_dados_climaticos.py
[2025-03-09T17:49:05.387+0000] {processor.py:914} INFO - Processing file /opt/airflow/dags/extra_dados_climaticos.py for tasks to queue
[2025-03-09T17:49:05.390+0000] {logging_mixin.py:190} INFO - [2025-03-09T17:49:05.390+0000] {dagbag.py:588} INFO - Filling up the DagBag from /opt/airflow/dags/extra_dados_climaticos.py
[2025-03-09T17:49:05.403+0000] {logging_mixin.py:190} INFO - [2025-03-09T17:49:05.402+0000] {dagbag.py:387} ERROR - Failed to import: /opt/airflow/dags/extra_dados_climaticos.py
Traceback (most recent call last):
  File "/home/airflow/.local/lib/python3.12/site-packages/airflow/models/dagbag.py", line 383, in parse
    loader.exec_module(new_module)
  File "<frozen importlib._bootstrap_external>", line 995, in exec_module
  File "<frozen importlib._bootstrap_external>", line 1133, in get_code
  File "<frozen importlib._bootstrap_external>", line 1063, in source_to_code
  File "<frozen importlib._bootstrap>", line 488, in _call_with_frames_removed
  File "/opt/airflow/dags/extra_dados_climaticos.py", line 41
    tarefa_1 >> tarefa_2ile_path + 'condicoes.csv')
                                                  ^
SyntaxError: unmatched ')'
[2025-03-09T17:49:05.404+0000] {processor.py:927} WARNING - No viable dags retrieved from /opt/airflow/dags/extra_dados_climaticos.py
[2025-03-09T17:49:05.432+0000] {processor.py:208} INFO - Processing /opt/airflow/dags/extra_dados_climaticos.py took 0.054 seconds
[2025-03-09T17:49:35.875+0000] {processor.py:186} INFO - Started process (PID=592) to work on /opt/airflow/dags/extra_dados_climaticos.py
[2025-03-09T17:49:35.877+0000] {processor.py:914} INFO - Processing file /opt/airflow/dags/extra_dados_climaticos.py for tasks to queue
[2025-03-09T17:49:35.880+0000] {logging_mixin.py:190} INFO - [2025-03-09T17:49:35.880+0000] {dagbag.py:588} INFO - Filling up the DagBag from /opt/airflow/dags/extra_dados_climaticos.py
[2025-03-09T17:49:35.900+0000] {logging_mixin.py:190} INFO - [2025-03-09T17:49:35.899+0000] {dagbag.py:387} ERROR - Failed to import: /opt/airflow/dags/extra_dados_climaticos.py
Traceback (most recent call last):
  File "/home/airflow/.local/lib/python3.12/site-packages/airflow/models/dagbag.py", line 383, in parse
    loader.exec_module(new_module)
  File "<frozen importlib._bootstrap_external>", line 995, in exec_module
  File "<frozen importlib._bootstrap_external>", line 1133, in get_code
  File "<frozen importlib._bootstrap_external>", line 1063, in source_to_code
  File "<frozen importlib._bootstrap>", line 488, in _call_with_frames_removed
  File "/opt/airflow/dags/extra_dados_climaticos.py", line 41
    tarefa_1 >> tarefa_2ile_path + 'condicoes.csv')
                                                  ^
SyntaxError: unmatched ')'
[2025-03-09T17:49:35.901+0000] {processor.py:927} WARNING - No viable dags retrieved from /opt/airflow/dags/extra_dados_climaticos.py
[2025-03-09T17:49:35.934+0000] {processor.py:208} INFO - Processing /opt/airflow/dags/extra_dados_climaticos.py took 0.070 seconds
[2025-03-09T17:50:06.613+0000] {processor.py:186} INFO - Started process (PID=657) to work on /opt/airflow/dags/extra_dados_climaticos.py
[2025-03-09T17:50:06.614+0000] {processor.py:914} INFO - Processing file /opt/airflow/dags/extra_dados_climaticos.py for tasks to queue
[2025-03-09T17:50:06.620+0000] {logging_mixin.py:190} INFO - [2025-03-09T17:50:06.619+0000] {dagbag.py:588} INFO - Filling up the DagBag from /opt/airflow/dags/extra_dados_climaticos.py
[2025-03-09T17:50:06.642+0000] {logging_mixin.py:190} INFO - [2025-03-09T17:50:06.641+0000] {dagbag.py:387} ERROR - Failed to import: /opt/airflow/dags/extra_dados_climaticos.py
Traceback (most recent call last):
  File "/home/airflow/.local/lib/python3.12/site-packages/airflow/models/dagbag.py", line 383, in parse
    loader.exec_module(new_module)
  File "<frozen importlib._bootstrap_external>", line 995, in exec_module
  File "<frozen importlib._bootstrap_external>", line 1133, in get_code
  File "<frozen importlib._bootstrap_external>", line 1063, in source_to_code
  File "<frozen importlib._bootstrap>", line 488, in _call_with_frames_removed
  File "/opt/airflow/dags/extra_dados_climaticos.py", line 41
    tarefa_1 >> tarefa_2ile_path + 'condicoes.csv')
                                                  ^
SyntaxError: unmatched ')'
[2025-03-09T17:50:06.644+0000] {processor.py:927} WARNING - No viable dags retrieved from /opt/airflow/dags/extra_dados_climaticos.py
[2025-03-09T17:50:06.669+0000] {processor.py:208} INFO - Processing /opt/airflow/dags/extra_dados_climaticos.py took 0.069 seconds
[2025-03-09T17:50:37.672+0000] {processor.py:186} INFO - Started process (PID=724) to work on /opt/airflow/dags/extra_dados_climaticos.py
[2025-03-09T17:50:37.673+0000] {processor.py:914} INFO - Processing file /opt/airflow/dags/extra_dados_climaticos.py for tasks to queue
[2025-03-09T17:50:37.676+0000] {logging_mixin.py:190} INFO - [2025-03-09T17:50:37.676+0000] {dagbag.py:588} INFO - Filling up the DagBag from /opt/airflow/dags/extra_dados_climaticos.py
[2025-03-09T17:50:37.694+0000] {logging_mixin.py:190} INFO - [2025-03-09T17:50:37.693+0000] {dagbag.py:387} ERROR - Failed to import: /opt/airflow/dags/extra_dados_climaticos.py
Traceback (most recent call last):
  File "/home/airflow/.local/lib/python3.12/site-packages/airflow/models/dagbag.py", line 383, in parse
    loader.exec_module(new_module)
  File "<frozen importlib._bootstrap_external>", line 995, in exec_module
  File "<frozen importlib._bootstrap_external>", line 1133, in get_code
  File "<frozen importlib._bootstrap_external>", line 1063, in source_to_code
  File "<frozen importlib._bootstrap>", line 488, in _call_with_frames_removed
  File "/opt/airflow/dags/extra_dados_climaticos.py", line 41
    tarefa_1 >> tarefa_2ile_path + 'condicoes.csv')
                                                  ^
SyntaxError: unmatched ')'
[2025-03-09T17:50:37.695+0000] {processor.py:927} WARNING - No viable dags retrieved from /opt/airflow/dags/extra_dados_climaticos.py
[2025-03-09T17:50:37.720+0000] {processor.py:208} INFO - Processing /opt/airflow/dags/extra_dados_climaticos.py took 0.054 seconds
[2025-03-09T17:51:08.382+0000] {processor.py:186} INFO - Started process (PID=789) to work on /opt/airflow/dags/extra_dados_climaticos.py
[2025-03-09T17:51:08.383+0000] {processor.py:914} INFO - Processing file /opt/airflow/dags/extra_dados_climaticos.py for tasks to queue
[2025-03-09T17:51:08.387+0000] {logging_mixin.py:190} INFO - [2025-03-09T17:51:08.386+0000] {dagbag.py:588} INFO - Filling up the DagBag from /opt/airflow/dags/extra_dados_climaticos.py
[2025-03-09T17:51:08.400+0000] {logging_mixin.py:190} INFO - [2025-03-09T17:51:08.399+0000] {dagbag.py:387} ERROR - Failed to import: /opt/airflow/dags/extra_dados_climaticos.py
Traceback (most recent call last):
  File "/home/airflow/.local/lib/python3.12/site-packages/airflow/models/dagbag.py", line 383, in parse
    loader.exec_module(new_module)
  File "<frozen importlib._bootstrap_external>", line 995, in exec_module
  File "<frozen importlib._bootstrap_external>", line 1133, in get_code
  File "<frozen importlib._bootstrap_external>", line 1063, in source_to_code
  File "<frozen importlib._bootstrap>", line 488, in _call_with_frames_removed
  File "/opt/airflow/dags/extra_dados_climaticos.py", line 41
    tarefa_1 >> tarefa_2ile_path + 'condicoes.csv')
                                                  ^
SyntaxError: unmatched ')'
[2025-03-09T17:51:08.401+0000] {processor.py:927} WARNING - No viable dags retrieved from /opt/airflow/dags/extra_dados_climaticos.py
[2025-03-09T17:51:08.421+0000] {processor.py:208} INFO - Processing /opt/airflow/dags/extra_dados_climaticos.py took 0.045 seconds
[2025-03-09T17:51:40.329+0000] {processor.py:186} INFO - Started process (PID=855) to work on /opt/airflow/dags/extra_dados_climaticos.py
[2025-03-09T17:51:40.330+0000] {processor.py:914} INFO - Processing file /opt/airflow/dags/extra_dados_climaticos.py for tasks to queue
[2025-03-09T17:51:40.332+0000] {logging_mixin.py:190} INFO - [2025-03-09T17:51:40.332+0000] {dagbag.py:588} INFO - Filling up the DagBag from /opt/airflow/dags/extra_dados_climaticos.py
[2025-03-09T17:51:40.346+0000] {logging_mixin.py:190} INFO - [2025-03-09T17:51:40.344+0000] {dagbag.py:387} ERROR - Failed to import: /opt/airflow/dags/extra_dados_climaticos.py
Traceback (most recent call last):
  File "/home/airflow/.local/lib/python3.12/site-packages/airflow/models/dagbag.py", line 383, in parse
    loader.exec_module(new_module)
  File "<frozen importlib._bootstrap_external>", line 995, in exec_module
  File "<frozen importlib._bootstrap_external>", line 1133, in get_code
  File "<frozen importlib._bootstrap_external>", line 1063, in source_to_code
  File "<frozen importlib._bootstrap>", line 488, in _call_with_frames_removed
  File "/opt/airflow/dags/extra_dados_climaticos.py", line 41
    tarefa_1 >> tarefa_2ile_path + 'condicoes.csv')
                                                  ^
SyntaxError: unmatched ')'
[2025-03-09T17:51:40.348+0000] {processor.py:927} WARNING - No viable dags retrieved from /opt/airflow/dags/extra_dados_climaticos.py
[2025-03-09T17:51:40.370+0000] {processor.py:208} INFO - Processing /opt/airflow/dags/extra_dados_climaticos.py took 0.046 seconds
[2025-03-09T17:52:10.923+0000] {processor.py:186} INFO - Started process (PID=921) to work on /opt/airflow/dags/extra_dados_climaticos.py
[2025-03-09T17:52:10.925+0000] {processor.py:914} INFO - Processing file /opt/airflow/dags/extra_dados_climaticos.py for tasks to queue
[2025-03-09T17:52:10.929+0000] {logging_mixin.py:190} INFO - [2025-03-09T17:52:10.928+0000] {dagbag.py:588} INFO - Filling up the DagBag from /opt/airflow/dags/extra_dados_climaticos.py
[2025-03-09T17:52:10.960+0000] {logging_mixin.py:190} INFO - [2025-03-09T17:52:10.958+0000] {dagbag.py:387} ERROR - Failed to import: /opt/airflow/dags/extra_dados_climaticos.py
Traceback (most recent call last):
  File "/home/airflow/.local/lib/python3.12/site-packages/airflow/models/dagbag.py", line 383, in parse
    loader.exec_module(new_module)
  File "<frozen importlib._bootstrap_external>", line 995, in exec_module
  File "<frozen importlib._bootstrap_external>", line 1133, in get_code
  File "<frozen importlib._bootstrap_external>", line 1063, in source_to_code
  File "<frozen importlib._bootstrap>", line 488, in _call_with_frames_removed
  File "/opt/airflow/dags/extra_dados_climaticos.py", line 41
    tarefa_1 >> tarefa_2ile_path + 'condicoes.csv')
                                                  ^
SyntaxError: unmatched ')'
[2025-03-09T17:52:10.962+0000] {processor.py:927} WARNING - No viable dags retrieved from /opt/airflow/dags/extra_dados_climaticos.py
[2025-03-09T17:52:11.010+0000] {processor.py:208} INFO - Processing /opt/airflow/dags/extra_dados_climaticos.py took 0.115 seconds
[2025-03-09T17:52:42.634+0000] {processor.py:186} INFO - Started process (PID=987) to work on /opt/airflow/dags/extra_dados_climaticos.py
[2025-03-09T17:52:42.636+0000] {processor.py:914} INFO - Processing file /opt/airflow/dags/extra_dados_climaticos.py for tasks to queue
[2025-03-09T17:52:42.639+0000] {logging_mixin.py:190} INFO - [2025-03-09T17:52:42.638+0000] {dagbag.py:588} INFO - Filling up the DagBag from /opt/airflow/dags/extra_dados_climaticos.py
[2025-03-09T17:52:42.658+0000] {logging_mixin.py:190} INFO - [2025-03-09T17:52:42.656+0000] {dagbag.py:387} ERROR - Failed to import: /opt/airflow/dags/extra_dados_climaticos.py
Traceback (most recent call last):
  File "/home/airflow/.local/lib/python3.12/site-packages/airflow/models/dagbag.py", line 383, in parse
    loader.exec_module(new_module)
  File "<frozen importlib._bootstrap_external>", line 995, in exec_module
  File "<frozen importlib._bootstrap_external>", line 1133, in get_code
  File "<frozen importlib._bootstrap_external>", line 1063, in source_to_code
  File "<frozen importlib._bootstrap>", line 488, in _call_with_frames_removed
  File "/opt/airflow/dags/extra_dados_climaticos.py", line 41
    tarefa_1 >> tarefa_2ile_path + 'condicoes.csv')
                                                  ^
SyntaxError: unmatched ')'
[2025-03-09T17:52:42.659+0000] {processor.py:927} WARNING - No viable dags retrieved from /opt/airflow/dags/extra_dados_climaticos.py
[2025-03-09T17:52:42.680+0000] {processor.py:208} INFO - Processing /opt/airflow/dags/extra_dados_climaticos.py took 0.051 seconds
[2025-03-09T17:53:13.789+0000] {processor.py:186} INFO - Started process (PID=1053) to work on /opt/airflow/dags/extra_dados_climaticos.py
[2025-03-09T17:53:13.790+0000] {processor.py:914} INFO - Processing file /opt/airflow/dags/extra_dados_climaticos.py for tasks to queue
[2025-03-09T17:53:13.793+0000] {logging_mixin.py:190} INFO - [2025-03-09T17:53:13.792+0000] {dagbag.py:588} INFO - Filling up the DagBag from /opt/airflow/dags/extra_dados_climaticos.py
[2025-03-09T17:53:13.807+0000] {logging_mixin.py:190} INFO - [2025-03-09T17:53:13.806+0000] {dagbag.py:387} ERROR - Failed to import: /opt/airflow/dags/extra_dados_climaticos.py
Traceback (most recent call last):
  File "/home/airflow/.local/lib/python3.12/site-packages/airflow/models/dagbag.py", line 383, in parse
    loader.exec_module(new_module)
  File "<frozen importlib._bootstrap_external>", line 995, in exec_module
  File "<frozen importlib._bootstrap_external>", line 1133, in get_code
  File "<frozen importlib._bootstrap_external>", line 1063, in source_to_code
  File "<frozen importlib._bootstrap>", line 488, in _call_with_frames_removed
  File "/opt/airflow/dags/extra_dados_climaticos.py", line 41
    tarefa_1 >> tarefa_2ile_path + 'condicoes.csv')
                                                  ^
SyntaxError: unmatched ')'
[2025-03-09T17:53:13.808+0000] {processor.py:927} WARNING - No viable dags retrieved from /opt/airflow/dags/extra_dados_climaticos.py
[2025-03-09T17:53:13.833+0000] {processor.py:208} INFO - Processing /opt/airflow/dags/extra_dados_climaticos.py took 0.049 seconds
[2025-03-09T17:53:45.342+0000] {processor.py:186} INFO - Started process (PID=1119) to work on /opt/airflow/dags/extra_dados_climaticos.py
[2025-03-09T17:53:45.343+0000] {processor.py:914} INFO - Processing file /opt/airflow/dags/extra_dados_climaticos.py for tasks to queue
[2025-03-09T17:53:45.346+0000] {logging_mixin.py:190} INFO - [2025-03-09T17:53:45.345+0000] {dagbag.py:588} INFO - Filling up the DagBag from /opt/airflow/dags/extra_dados_climaticos.py
[2025-03-09T17:53:45.363+0000] {logging_mixin.py:190} INFO - [2025-03-09T17:53:45.362+0000] {dagbag.py:387} ERROR - Failed to import: /opt/airflow/dags/extra_dados_climaticos.py
Traceback (most recent call last):
  File "/home/airflow/.local/lib/python3.12/site-packages/airflow/models/dagbag.py", line 383, in parse
    loader.exec_module(new_module)
  File "<frozen importlib._bootstrap_external>", line 995, in exec_module
  File "<frozen importlib._bootstrap_external>", line 1133, in get_code
  File "<frozen importlib._bootstrap_external>", line 1063, in source_to_code
  File "<frozen importlib._bootstrap>", line 488, in _call_with_frames_removed
  File "/opt/airflow/dags/extra_dados_climaticos.py", line 41
    tarefa_1 >> tarefa_2ile_path + 'condicoes.csv')
                                                  ^
SyntaxError: unmatched ')'
[2025-03-09T17:53:45.363+0000] {processor.py:927} WARNING - No viable dags retrieved from /opt/airflow/dags/extra_dados_climaticos.py
[2025-03-09T17:53:45.384+0000] {processor.py:208} INFO - Processing /opt/airflow/dags/extra_dados_climaticos.py took 0.048 seconds
[2025-03-09T17:54:16.769+0000] {processor.py:186} INFO - Started process (PID=1185) to work on /opt/airflow/dags/extra_dados_climaticos.py
[2025-03-09T17:54:16.771+0000] {processor.py:914} INFO - Processing file /opt/airflow/dags/extra_dados_climaticos.py for tasks to queue
[2025-03-09T17:54:16.777+0000] {logging_mixin.py:190} INFO - [2025-03-09T17:54:16.776+0000] {dagbag.py:588} INFO - Filling up the DagBag from /opt/airflow/dags/extra_dados_climaticos.py
[2025-03-09T17:54:16.803+0000] {logging_mixin.py:190} INFO - [2025-03-09T17:54:16.801+0000] {dagbag.py:387} ERROR - Failed to import: /opt/airflow/dags/extra_dados_climaticos.py
Traceback (most recent call last):
  File "/home/airflow/.local/lib/python3.12/site-packages/airflow/models/dagbag.py", line 383, in parse
    loader.exec_module(new_module)
  File "<frozen importlib._bootstrap_external>", line 995, in exec_module
  File "<frozen importlib._bootstrap_external>", line 1133, in get_code
  File "<frozen importlib._bootstrap_external>", line 1063, in source_to_code
  File "<frozen importlib._bootstrap>", line 488, in _call_with_frames_removed
  File "/opt/airflow/dags/extra_dados_climaticos.py", line 41
    tarefa_1 >> tarefa_2ile_path + 'condicoes.csv')
                                                  ^
SyntaxError: unmatched ')'
[2025-03-09T17:54:16.804+0000] {processor.py:927} WARNING - No viable dags retrieved from /opt/airflow/dags/extra_dados_climaticos.py
[2025-03-09T17:54:16.855+0000] {processor.py:208} INFO - Processing /opt/airflow/dags/extra_dados_climaticos.py took 0.096 seconds
[2025-03-09T17:54:48.053+0000] {processor.py:186} INFO - Started process (PID=1251) to work on /opt/airflow/dags/extra_dados_climaticos.py
[2025-03-09T17:54:48.055+0000] {processor.py:914} INFO - Processing file /opt/airflow/dags/extra_dados_climaticos.py for tasks to queue
[2025-03-09T17:54:48.057+0000] {logging_mixin.py:190} INFO - [2025-03-09T17:54:48.057+0000] {dagbag.py:588} INFO - Filling up the DagBag from /opt/airflow/dags/extra_dados_climaticos.py
[2025-03-09T17:54:48.073+0000] {logging_mixin.py:190} INFO - [2025-03-09T17:54:48.072+0000] {dagbag.py:387} ERROR - Failed to import: /opt/airflow/dags/extra_dados_climaticos.py
Traceback (most recent call last):
  File "/home/airflow/.local/lib/python3.12/site-packages/airflow/models/dagbag.py", line 383, in parse
    loader.exec_module(new_module)
  File "<frozen importlib._bootstrap_external>", line 995, in exec_module
  File "<frozen importlib._bootstrap_external>", line 1133, in get_code
  File "<frozen importlib._bootstrap_external>", line 1063, in source_to_code
  File "<frozen importlib._bootstrap>", line 488, in _call_with_frames_removed
  File "/opt/airflow/dags/extra_dados_climaticos.py", line 41
    tarefa_1 >> tarefa_2ile_path + 'condicoes.csv')
                                                  ^
SyntaxError: unmatched ')'
[2025-03-09T17:54:48.074+0000] {processor.py:927} WARNING - No viable dags retrieved from /opt/airflow/dags/extra_dados_climaticos.py
[2025-03-09T17:54:48.109+0000] {processor.py:208} INFO - Processing /opt/airflow/dags/extra_dados_climaticos.py took 0.062 seconds
[2025-03-09T17:55:19.276+0000] {processor.py:186} INFO - Started process (PID=1317) to work on /opt/airflow/dags/extra_dados_climaticos.py
[2025-03-09T17:55:19.278+0000] {processor.py:914} INFO - Processing file /opt/airflow/dags/extra_dados_climaticos.py for tasks to queue
[2025-03-09T17:55:19.281+0000] {logging_mixin.py:190} INFO - [2025-03-09T17:55:19.281+0000] {dagbag.py:588} INFO - Filling up the DagBag from /opt/airflow/dags/extra_dados_climaticos.py
[2025-03-09T17:55:19.294+0000] {logging_mixin.py:190} INFO - [2025-03-09T17:55:19.293+0000] {dagbag.py:387} ERROR - Failed to import: /opt/airflow/dags/extra_dados_climaticos.py
Traceback (most recent call last):
  File "/home/airflow/.local/lib/python3.12/site-packages/airflow/models/dagbag.py", line 383, in parse
    loader.exec_module(new_module)
  File "<frozen importlib._bootstrap_external>", line 995, in exec_module
  File "<frozen importlib._bootstrap_external>", line 1133, in get_code
  File "<frozen importlib._bootstrap_external>", line 1063, in source_to_code
  File "<frozen importlib._bootstrap>", line 488, in _call_with_frames_removed
  File "/opt/airflow/dags/extra_dados_climaticos.py", line 41
    tarefa_1 >> tarefa_2ile_path + 'condicoes.csv')
                                                  ^
SyntaxError: unmatched ')'
[2025-03-09T17:55:19.295+0000] {processor.py:927} WARNING - No viable dags retrieved from /opt/airflow/dags/extra_dados_climaticos.py
[2025-03-09T17:55:19.316+0000] {processor.py:208} INFO - Processing /opt/airflow/dags/extra_dados_climaticos.py took 0.045 seconds
[2025-03-09T17:55:50.650+0000] {processor.py:186} INFO - Started process (PID=1383) to work on /opt/airflow/dags/extra_dados_climaticos.py
[2025-03-09T17:55:50.653+0000] {processor.py:914} INFO - Processing file /opt/airflow/dags/extra_dados_climaticos.py for tasks to queue
[2025-03-09T17:55:50.658+0000] {logging_mixin.py:190} INFO - [2025-03-09T17:55:50.658+0000] {dagbag.py:588} INFO - Filling up the DagBag from /opt/airflow/dags/extra_dados_climaticos.py
[2025-03-09T17:55:50.677+0000] {logging_mixin.py:190} INFO - [2025-03-09T17:55:50.675+0000] {dagbag.py:387} ERROR - Failed to import: /opt/airflow/dags/extra_dados_climaticos.py
Traceback (most recent call last):
  File "/home/airflow/.local/lib/python3.12/site-packages/airflow/models/dagbag.py", line 383, in parse
    loader.exec_module(new_module)
  File "<frozen importlib._bootstrap_external>", line 995, in exec_module
  File "<frozen importlib._bootstrap_external>", line 1133, in get_code
  File "<frozen importlib._bootstrap_external>", line 1063, in source_to_code
  File "<frozen importlib._bootstrap>", line 488, in _call_with_frames_removed
  File "/opt/airflow/dags/extra_dados_climaticos.py", line 41
    tarefa_1 >> tarefa_2ile_path + 'condicoes.csv')
                                                  ^
SyntaxError: unmatched ')'
[2025-03-09T17:55:50.678+0000] {processor.py:927} WARNING - No viable dags retrieved from /opt/airflow/dags/extra_dados_climaticos.py
[2025-03-09T17:55:50.753+0000] {processor.py:208} INFO - Processing /opt/airflow/dags/extra_dados_climaticos.py took 0.113 seconds
[2025-03-09T17:56:21.774+0000] {processor.py:186} INFO - Started process (PID=1449) to work on /opt/airflow/dags/extra_dados_climaticos.py
[2025-03-09T17:56:21.775+0000] {processor.py:914} INFO - Processing file /opt/airflow/dags/extra_dados_climaticos.py for tasks to queue
[2025-03-09T17:56:21.781+0000] {logging_mixin.py:190} INFO - [2025-03-09T17:56:21.780+0000] {dagbag.py:588} INFO - Filling up the DagBag from /opt/airflow/dags/extra_dados_climaticos.py
[2025-03-09T17:56:21.802+0000] {logging_mixin.py:190} INFO - [2025-03-09T17:56:21.801+0000] {dagbag.py:387} ERROR - Failed to import: /opt/airflow/dags/extra_dados_climaticos.py
Traceback (most recent call last):
  File "/home/airflow/.local/lib/python3.12/site-packages/airflow/models/dagbag.py", line 383, in parse
    loader.exec_module(new_module)
  File "<frozen importlib._bootstrap_external>", line 995, in exec_module
  File "<frozen importlib._bootstrap_external>", line 1133, in get_code
  File "<frozen importlib._bootstrap_external>", line 1063, in source_to_code
  File "<frozen importlib._bootstrap>", line 488, in _call_with_frames_removed
  File "/opt/airflow/dags/extra_dados_climaticos.py", line 41
    tarefa_1 >> tarefa_2ile_path + 'condicoes.csv')
                                                  ^
SyntaxError: unmatched ')'
[2025-03-09T17:56:21.804+0000] {processor.py:927} WARNING - No viable dags retrieved from /opt/airflow/dags/extra_dados_climaticos.py
[2025-03-09T17:56:21.838+0000] {processor.py:208} INFO - Processing /opt/airflow/dags/extra_dados_climaticos.py took 0.076 seconds
[2025-03-09T17:56:53.342+0000] {processor.py:186} INFO - Started process (PID=1515) to work on /opt/airflow/dags/extra_dados_climaticos.py
[2025-03-09T17:56:53.343+0000] {processor.py:914} INFO - Processing file /opt/airflow/dags/extra_dados_climaticos.py for tasks to queue
[2025-03-09T17:56:53.352+0000] {logging_mixin.py:190} INFO - [2025-03-09T17:56:53.351+0000] {dagbag.py:588} INFO - Filling up the DagBag from /opt/airflow/dags/extra_dados_climaticos.py
[2025-03-09T17:56:53.363+0000] {logging_mixin.py:190} INFO - [2025-03-09T17:56:53.362+0000] {dagbag.py:387} ERROR - Failed to import: /opt/airflow/dags/extra_dados_climaticos.py
Traceback (most recent call last):
  File "/home/airflow/.local/lib/python3.12/site-packages/airflow/models/dagbag.py", line 383, in parse
    loader.exec_module(new_module)
  File "<frozen importlib._bootstrap_external>", line 995, in exec_module
  File "<frozen importlib._bootstrap_external>", line 1133, in get_code
  File "<frozen importlib._bootstrap_external>", line 1063, in source_to_code
  File "<frozen importlib._bootstrap>", line 488, in _call_with_frames_removed
  File "/opt/airflow/dags/extra_dados_climaticos.py", line 41
    tarefa_1 >> tarefa_2ile_path + 'condicoes.csv')
                                                  ^
SyntaxError: unmatched ')'
[2025-03-09T17:56:53.364+0000] {processor.py:927} WARNING - No viable dags retrieved from /opt/airflow/dags/extra_dados_climaticos.py
[2025-03-09T17:56:53.392+0000] {processor.py:208} INFO - Processing /opt/airflow/dags/extra_dados_climaticos.py took 0.058 seconds
[2025-03-09T17:57:25.092+0000] {processor.py:186} INFO - Started process (PID=1581) to work on /opt/airflow/dags/extra_dados_climaticos.py
[2025-03-09T17:57:25.115+0000] {processor.py:914} INFO - Processing file /opt/airflow/dags/extra_dados_climaticos.py for tasks to queue
[2025-03-09T17:57:25.118+0000] {logging_mixin.py:190} INFO - [2025-03-09T17:57:25.117+0000] {dagbag.py:588} INFO - Filling up the DagBag from /opt/airflow/dags/extra_dados_climaticos.py
[2025-03-09T17:57:25.131+0000] {logging_mixin.py:190} INFO - [2025-03-09T17:57:25.130+0000] {dagbag.py:387} ERROR - Failed to import: /opt/airflow/dags/extra_dados_climaticos.py
Traceback (most recent call last):
  File "/home/airflow/.local/lib/python3.12/site-packages/airflow/models/dagbag.py", line 383, in parse
    loader.exec_module(new_module)
  File "<frozen importlib._bootstrap_external>", line 995, in exec_module
  File "<frozen importlib._bootstrap_external>", line 1133, in get_code
  File "<frozen importlib._bootstrap_external>", line 1063, in source_to_code
  File "<frozen importlib._bootstrap>", line 488, in _call_with_frames_removed
  File "/opt/airflow/dags/extra_dados_climaticos.py", line 41
    tarefa_1 >> tarefa_2ile_path + 'condicoes.csv')
                                                  ^
SyntaxError: unmatched ')'
[2025-03-09T17:57:25.132+0000] {processor.py:927} WARNING - No viable dags retrieved from /opt/airflow/dags/extra_dados_climaticos.py
[2025-03-09T17:57:25.166+0000] {processor.py:208} INFO - Processing /opt/airflow/dags/extra_dados_climaticos.py took 0.080 seconds
[2025-03-09T17:57:55.523+0000] {processor.py:186} INFO - Started process (PID=1650) to work on /opt/airflow/dags/extra_dados_climaticos.py
[2025-03-09T17:57:55.524+0000] {processor.py:914} INFO - Processing file /opt/airflow/dags/extra_dados_climaticos.py for tasks to queue
[2025-03-09T17:57:55.528+0000] {logging_mixin.py:190} INFO - [2025-03-09T17:57:55.527+0000] {dagbag.py:588} INFO - Filling up the DagBag from /opt/airflow/dags/extra_dados_climaticos.py
[2025-03-09T17:57:55.540+0000] {logging_mixin.py:190} INFO - [2025-03-09T17:57:55.538+0000] {dagbag.py:387} ERROR - Failed to import: /opt/airflow/dags/extra_dados_climaticos.py
Traceback (most recent call last):
  File "/home/airflow/.local/lib/python3.12/site-packages/airflow/models/dagbag.py", line 383, in parse
    loader.exec_module(new_module)
  File "<frozen importlib._bootstrap_external>", line 995, in exec_module
  File "<frozen importlib._bootstrap_external>", line 1133, in get_code
  File "<frozen importlib._bootstrap_external>", line 1063, in source_to_code
  File "<frozen importlib._bootstrap>", line 488, in _call_with_frames_removed
  File "/opt/airflow/dags/extra_dados_climaticos.py", line 41
    tarefa_1 >> tarefa_2ile_path + 'condicoes.csv')
                                                  ^
SyntaxError: unmatched ')'
[2025-03-09T17:57:55.541+0000] {processor.py:927} WARNING - No viable dags retrieved from /opt/airflow/dags/extra_dados_climaticos.py
[2025-03-09T17:57:55.563+0000] {processor.py:208} INFO - Processing /opt/airflow/dags/extra_dados_climaticos.py took 0.046 seconds
[2025-03-09T17:58:26.107+0000] {processor.py:186} INFO - Started process (PID=1716) to work on /opt/airflow/dags/extra_dados_climaticos.py
[2025-03-09T17:58:26.109+0000] {processor.py:914} INFO - Processing file /opt/airflow/dags/extra_dados_climaticos.py for tasks to queue
[2025-03-09T17:58:26.116+0000] {logging_mixin.py:190} INFO - [2025-03-09T17:58:26.116+0000] {dagbag.py:588} INFO - Filling up the DagBag from /opt/airflow/dags/extra_dados_climaticos.py
[2025-03-09T17:58:26.136+0000] {logging_mixin.py:190} INFO - [2025-03-09T17:58:26.135+0000] {dagbag.py:387} ERROR - Failed to import: /opt/airflow/dags/extra_dados_climaticos.py
Traceback (most recent call last):
  File "/home/airflow/.local/lib/python3.12/site-packages/airflow/models/dagbag.py", line 383, in parse
    loader.exec_module(new_module)
  File "<frozen importlib._bootstrap_external>", line 995, in exec_module
  File "<frozen importlib._bootstrap_external>", line 1133, in get_code
  File "<frozen importlib._bootstrap_external>", line 1063, in source_to_code
  File "<frozen importlib._bootstrap>", line 488, in _call_with_frames_removed
  File "/opt/airflow/dags/extra_dados_climaticos.py", line 41
    tarefa_1 >> tarefa_2ile_path + 'condicoes.csv')
                                                  ^
SyntaxError: unmatched ')'
[2025-03-09T17:58:26.138+0000] {processor.py:927} WARNING - No viable dags retrieved from /opt/airflow/dags/extra_dados_climaticos.py
[2025-03-09T17:58:26.183+0000] {processor.py:208} INFO - Processing /opt/airflow/dags/extra_dados_climaticos.py took 0.086 seconds
[2025-03-09T17:58:56.885+0000] {processor.py:186} INFO - Started process (PID=1782) to work on /opt/airflow/dags/extra_dados_climaticos.py
[2025-03-09T17:58:56.886+0000] {processor.py:914} INFO - Processing file /opt/airflow/dags/extra_dados_climaticos.py for tasks to queue
[2025-03-09T17:58:56.888+0000] {logging_mixin.py:190} INFO - [2025-03-09T17:58:56.888+0000] {dagbag.py:588} INFO - Filling up the DagBag from /opt/airflow/dags/extra_dados_climaticos.py
[2025-03-09T17:58:56.901+0000] {logging_mixin.py:190} INFO - [2025-03-09T17:58:56.900+0000] {dagbag.py:387} ERROR - Failed to import: /opt/airflow/dags/extra_dados_climaticos.py
Traceback (most recent call last):
  File "/home/airflow/.local/lib/python3.12/site-packages/airflow/models/dagbag.py", line 383, in parse
    loader.exec_module(new_module)
  File "<frozen importlib._bootstrap_external>", line 995, in exec_module
  File "<frozen importlib._bootstrap_external>", line 1133, in get_code
  File "<frozen importlib._bootstrap_external>", line 1063, in source_to_code
  File "<frozen importlib._bootstrap>", line 488, in _call_with_frames_removed
  File "/opt/airflow/dags/extra_dados_climaticos.py", line 41
    tarefa_1 >> tarefa_2ile_path + 'condicoes.csv')
                                                  ^
SyntaxError: unmatched ')'
[2025-03-09T17:58:56.902+0000] {processor.py:927} WARNING - No viable dags retrieved from /opt/airflow/dags/extra_dados_climaticos.py
[2025-03-09T17:58:56.923+0000] {processor.py:208} INFO - Processing /opt/airflow/dags/extra_dados_climaticos.py took 0.045 seconds
[2025-03-09T17:59:27.380+0000] {processor.py:186} INFO - Started process (PID=1848) to work on /opt/airflow/dags/extra_dados_climaticos.py
[2025-03-09T17:59:27.381+0000] {processor.py:914} INFO - Processing file /opt/airflow/dags/extra_dados_climaticos.py for tasks to queue
[2025-03-09T17:59:27.384+0000] {logging_mixin.py:190} INFO - [2025-03-09T17:59:27.383+0000] {dagbag.py:588} INFO - Filling up the DagBag from /opt/airflow/dags/extra_dados_climaticos.py
[2025-03-09T17:59:27.401+0000] {logging_mixin.py:190} INFO - [2025-03-09T17:59:27.400+0000] {dagbag.py:387} ERROR - Failed to import: /opt/airflow/dags/extra_dados_climaticos.py
Traceback (most recent call last):
  File "/home/airflow/.local/lib/python3.12/site-packages/airflow/models/dagbag.py", line 383, in parse
    loader.exec_module(new_module)
  File "<frozen importlib._bootstrap_external>", line 995, in exec_module
  File "<frozen importlib._bootstrap_external>", line 1133, in get_code
  File "<frozen importlib._bootstrap_external>", line 1063, in source_to_code
  File "<frozen importlib._bootstrap>", line 488, in _call_with_frames_removed
  File "/opt/airflow/dags/extra_dados_climaticos.py", line 41
    tarefa_1 >> tarefa_2ile_path + 'condicoes.csv')
                                                  ^
SyntaxError: unmatched ')'
[2025-03-09T17:59:27.402+0000] {processor.py:927} WARNING - No viable dags retrieved from /opt/airflow/dags/extra_dados_climaticos.py
[2025-03-09T17:59:27.434+0000] {processor.py:208} INFO - Processing /opt/airflow/dags/extra_dados_climaticos.py took 0.062 seconds
[2025-03-09T17:59:57.981+0000] {processor.py:186} INFO - Started process (PID=1914) to work on /opt/airflow/dags/extra_dados_climaticos.py
[2025-03-09T17:59:57.983+0000] {processor.py:914} INFO - Processing file /opt/airflow/dags/extra_dados_climaticos.py for tasks to queue
[2025-03-09T17:59:57.988+0000] {logging_mixin.py:190} INFO - [2025-03-09T17:59:57.988+0000] {dagbag.py:588} INFO - Filling up the DagBag from /opt/airflow/dags/extra_dados_climaticos.py
[2025-03-09T17:59:58.019+0000] {logging_mixin.py:190} INFO - [2025-03-09T17:59:58.015+0000] {dagbag.py:387} ERROR - Failed to import: /opt/airflow/dags/extra_dados_climaticos.py
Traceback (most recent call last):
  File "/home/airflow/.local/lib/python3.12/site-packages/airflow/models/dagbag.py", line 383, in parse
    loader.exec_module(new_module)
  File "<frozen importlib._bootstrap_external>", line 995, in exec_module
  File "<frozen importlib._bootstrap_external>", line 1133, in get_code
  File "<frozen importlib._bootstrap_external>", line 1063, in source_to_code
  File "<frozen importlib._bootstrap>", line 488, in _call_with_frames_removed
  File "/opt/airflow/dags/extra_dados_climaticos.py", line 41
    tarefa_1 >> tarefa_2ile_path + 'condicoes.csv')
                                                  ^
SyntaxError: unmatched ')'
[2025-03-09T17:59:58.021+0000] {processor.py:927} WARNING - No viable dags retrieved from /opt/airflow/dags/extra_dados_climaticos.py
[2025-03-09T17:59:58.064+0000] {processor.py:208} INFO - Processing /opt/airflow/dags/extra_dados_climaticos.py took 0.093 seconds
[2025-03-09T18:00:28.228+0000] {processor.py:186} INFO - Started process (PID=1980) to work on /opt/airflow/dags/extra_dados_climaticos.py
[2025-03-09T18:00:28.229+0000] {processor.py:914} INFO - Processing file /opt/airflow/dags/extra_dados_climaticos.py for tasks to queue
[2025-03-09T18:00:28.231+0000] {logging_mixin.py:190} INFO - [2025-03-09T18:00:28.231+0000] {dagbag.py:588} INFO - Filling up the DagBag from /opt/airflow/dags/extra_dados_climaticos.py
[2025-03-09T18:00:28.242+0000] {logging_mixin.py:190} INFO - [2025-03-09T18:00:28.241+0000] {dagbag.py:387} ERROR - Failed to import: /opt/airflow/dags/extra_dados_climaticos.py
Traceback (most recent call last):
  File "/home/airflow/.local/lib/python3.12/site-packages/airflow/models/dagbag.py", line 383, in parse
    loader.exec_module(new_module)
  File "<frozen importlib._bootstrap_external>", line 995, in exec_module
  File "<frozen importlib._bootstrap_external>", line 1133, in get_code
  File "<frozen importlib._bootstrap_external>", line 1063, in source_to_code
  File "<frozen importlib._bootstrap>", line 488, in _call_with_frames_removed
  File "/opt/airflow/dags/extra_dados_climaticos.py", line 41
    tarefa_1 >> tarefa_2ile_path + 'condicoes.csv')
                                                  ^
SyntaxError: unmatched ')'
[2025-03-09T18:00:28.242+0000] {processor.py:927} WARNING - No viable dags retrieved from /opt/airflow/dags/extra_dados_climaticos.py
[2025-03-09T18:00:28.263+0000] {processor.py:208} INFO - Processing /opt/airflow/dags/extra_dados_climaticos.py took 0.042 seconds
[2025-03-09T18:00:58.712+0000] {processor.py:186} INFO - Started process (PID=2046) to work on /opt/airflow/dags/extra_dados_climaticos.py
[2025-03-09T18:00:58.713+0000] {processor.py:914} INFO - Processing file /opt/airflow/dags/extra_dados_climaticos.py for tasks to queue
[2025-03-09T18:00:58.715+0000] {logging_mixin.py:190} INFO - [2025-03-09T18:00:58.715+0000] {dagbag.py:588} INFO - Filling up the DagBag from /opt/airflow/dags/extra_dados_climaticos.py
[2025-03-09T18:00:58.729+0000] {logging_mixin.py:190} INFO - [2025-03-09T18:00:58.728+0000] {dagbag.py:387} ERROR - Failed to import: /opt/airflow/dags/extra_dados_climaticos.py
Traceback (most recent call last):
  File "/home/airflow/.local/lib/python3.12/site-packages/airflow/models/dagbag.py", line 383, in parse
    loader.exec_module(new_module)
  File "<frozen importlib._bootstrap_external>", line 995, in exec_module
  File "<frozen importlib._bootstrap_external>", line 1133, in get_code
  File "<frozen importlib._bootstrap_external>", line 1063, in source_to_code
  File "<frozen importlib._bootstrap>", line 488, in _call_with_frames_removed
  File "/opt/airflow/dags/extra_dados_climaticos.py", line 41
    tarefa_1 >> tarefa_2ile_path + 'condicoes.csv')
                                                  ^
SyntaxError: unmatched ')'
[2025-03-09T18:00:58.730+0000] {processor.py:927} WARNING - No viable dags retrieved from /opt/airflow/dags/extra_dados_climaticos.py
[2025-03-09T18:00:58.753+0000] {processor.py:208} INFO - Processing /opt/airflow/dags/extra_dados_climaticos.py took 0.048 seconds
[2025-03-09T18:01:28.859+0000] {processor.py:186} INFO - Started process (PID=2112) to work on /opt/airflow/dags/extra_dados_climaticos.py
[2025-03-09T18:01:28.860+0000] {processor.py:914} INFO - Processing file /opt/airflow/dags/extra_dados_climaticos.py for tasks to queue
[2025-03-09T18:01:28.864+0000] {logging_mixin.py:190} INFO - [2025-03-09T18:01:28.863+0000] {dagbag.py:588} INFO - Filling up the DagBag from /opt/airflow/dags/extra_dados_climaticos.py
[2025-03-09T18:01:28.877+0000] {logging_mixin.py:190} INFO - [2025-03-09T18:01:28.876+0000] {dagbag.py:387} ERROR - Failed to import: /opt/airflow/dags/extra_dados_climaticos.py
Traceback (most recent call last):
  File "/home/airflow/.local/lib/python3.12/site-packages/airflow/models/dagbag.py", line 383, in parse
    loader.exec_module(new_module)
  File "<frozen importlib._bootstrap_external>", line 995, in exec_module
  File "<frozen importlib._bootstrap_external>", line 1133, in get_code
  File "<frozen importlib._bootstrap_external>", line 1063, in source_to_code
  File "<frozen importlib._bootstrap>", line 488, in _call_with_frames_removed
  File "/opt/airflow/dags/extra_dados_climaticos.py", line 41
    tarefa_1 >> tarefa_2ile_path + 'condicoes.csv')
                                                  ^
SyntaxError: unmatched ')'
[2025-03-09T18:01:28.878+0000] {processor.py:927} WARNING - No viable dags retrieved from /opt/airflow/dags/extra_dados_climaticos.py
[2025-03-09T18:01:28.901+0000] {processor.py:208} INFO - Processing /opt/airflow/dags/extra_dados_climaticos.py took 0.048 seconds
[2025-03-09T18:01:59.148+0000] {processor.py:186} INFO - Started process (PID=2178) to work on /opt/airflow/dags/extra_dados_climaticos.py
[2025-03-09T18:01:59.149+0000] {processor.py:914} INFO - Processing file /opt/airflow/dags/extra_dados_climaticos.py for tasks to queue
[2025-03-09T18:01:59.151+0000] {logging_mixin.py:190} INFO - [2025-03-09T18:01:59.151+0000] {dagbag.py:588} INFO - Filling up the DagBag from /opt/airflow/dags/extra_dados_climaticos.py
[2025-03-09T18:01:59.164+0000] {logging_mixin.py:190} INFO - [2025-03-09T18:01:59.163+0000] {dagbag.py:387} ERROR - Failed to import: /opt/airflow/dags/extra_dados_climaticos.py
Traceback (most recent call last):
  File "/home/airflow/.local/lib/python3.12/site-packages/airflow/models/dagbag.py", line 383, in parse
    loader.exec_module(new_module)
  File "<frozen importlib._bootstrap_external>", line 995, in exec_module
  File "<frozen importlib._bootstrap_external>", line 1133, in get_code
  File "<frozen importlib._bootstrap_external>", line 1063, in source_to_code
  File "<frozen importlib._bootstrap>", line 488, in _call_with_frames_removed
  File "/opt/airflow/dags/extra_dados_climaticos.py", line 41
    tarefa_1 >> tarefa_2ile_path + 'condicoes.csv')
                                                  ^
SyntaxError: unmatched ')'
[2025-03-09T18:01:59.164+0000] {processor.py:927} WARNING - No viable dags retrieved from /opt/airflow/dags/extra_dados_climaticos.py
[2025-03-09T18:01:59.186+0000] {processor.py:208} INFO - Processing /opt/airflow/dags/extra_dados_climaticos.py took 0.043 seconds
[2025-03-09T18:02:29.981+0000] {processor.py:186} INFO - Started process (PID=2244) to work on /opt/airflow/dags/extra_dados_climaticos.py
[2025-03-09T18:02:29.985+0000] {processor.py:914} INFO - Processing file /opt/airflow/dags/extra_dados_climaticos.py for tasks to queue
[2025-03-09T18:02:29.989+0000] {logging_mixin.py:190} INFO - [2025-03-09T18:02:29.989+0000] {dagbag.py:588} INFO - Filling up the DagBag from /opt/airflow/dags/extra_dados_climaticos.py
[2025-03-09T18:02:30.002+0000] {logging_mixin.py:190} INFO - [2025-03-09T18:02:30.001+0000] {dagbag.py:387} ERROR - Failed to import: /opt/airflow/dags/extra_dados_climaticos.py
Traceback (most recent call last):
  File "/home/airflow/.local/lib/python3.12/site-packages/airflow/models/dagbag.py", line 383, in parse
    loader.exec_module(new_module)
  File "<frozen importlib._bootstrap_external>", line 995, in exec_module
  File "<frozen importlib._bootstrap_external>", line 1133, in get_code
  File "<frozen importlib._bootstrap_external>", line 1063, in source_to_code
  File "<frozen importlib._bootstrap>", line 488, in _call_with_frames_removed
  File "/opt/airflow/dags/extra_dados_climaticos.py", line 41
    tarefa_1 >> tarefa_2ile_path + 'condicoes.csv')
                                                  ^
SyntaxError: unmatched ')'
[2025-03-09T18:02:30.005+0000] {processor.py:927} WARNING - No viable dags retrieved from /opt/airflow/dags/extra_dados_climaticos.py
[2025-03-09T18:02:30.025+0000] {processor.py:208} INFO - Processing /opt/airflow/dags/extra_dados_climaticos.py took 0.050 seconds
[2025-03-09T18:03:00.416+0000] {processor.py:186} INFO - Started process (PID=2310) to work on /opt/airflow/dags/extra_dados_climaticos.py
[2025-03-09T18:03:00.417+0000] {processor.py:914} INFO - Processing file /opt/airflow/dags/extra_dados_climaticos.py for tasks to queue
[2025-03-09T18:03:00.420+0000] {logging_mixin.py:190} INFO - [2025-03-09T18:03:00.419+0000] {dagbag.py:588} INFO - Filling up the DagBag from /opt/airflow/dags/extra_dados_climaticos.py
[2025-03-09T18:03:00.438+0000] {logging_mixin.py:190} INFO - [2025-03-09T18:03:00.437+0000] {dagbag.py:387} ERROR - Failed to import: /opt/airflow/dags/extra_dados_climaticos.py
Traceback (most recent call last):
  File "/home/airflow/.local/lib/python3.12/site-packages/airflow/models/dagbag.py", line 383, in parse
    loader.exec_module(new_module)
  File "<frozen importlib._bootstrap_external>", line 995, in exec_module
  File "<frozen importlib._bootstrap_external>", line 1133, in get_code
  File "<frozen importlib._bootstrap_external>", line 1063, in source_to_code
  File "<frozen importlib._bootstrap>", line 488, in _call_with_frames_removed
  File "/opt/airflow/dags/extra_dados_climaticos.py", line 41
    tarefa_1 >> tarefa_2ile_path + 'condicoes.csv')
                                                  ^
SyntaxError: unmatched ')'
[2025-03-09T18:03:00.439+0000] {processor.py:927} WARNING - No viable dags retrieved from /opt/airflow/dags/extra_dados_climaticos.py
[2025-03-09T18:03:00.469+0000] {processor.py:208} INFO - Processing /opt/airflow/dags/extra_dados_climaticos.py took 0.060 seconds
[2025-03-09T18:03:31.334+0000] {processor.py:186} INFO - Started process (PID=2376) to work on /opt/airflow/dags/extra_dados_climaticos.py
[2025-03-09T18:03:31.336+0000] {processor.py:914} INFO - Processing file /opt/airflow/dags/extra_dados_climaticos.py for tasks to queue
[2025-03-09T18:03:31.340+0000] {logging_mixin.py:190} INFO - [2025-03-09T18:03:31.339+0000] {dagbag.py:588} INFO - Filling up the DagBag from /opt/airflow/dags/extra_dados_climaticos.py
[2025-03-09T18:03:31.360+0000] {logging_mixin.py:190} INFO - [2025-03-09T18:03:31.358+0000] {dagbag.py:387} ERROR - Failed to import: /opt/airflow/dags/extra_dados_climaticos.py
Traceback (most recent call last):
  File "/home/airflow/.local/lib/python3.12/site-packages/airflow/models/dagbag.py", line 383, in parse
    loader.exec_module(new_module)
  File "<frozen importlib._bootstrap_external>", line 995, in exec_module
  File "<frozen importlib._bootstrap_external>", line 1133, in get_code
  File "<frozen importlib._bootstrap_external>", line 1063, in source_to_code
  File "<frozen importlib._bootstrap>", line 488, in _call_with_frames_removed
  File "/opt/airflow/dags/extra_dados_climaticos.py", line 41
    tarefa_1 >> tarefa_2ile_path + 'condicoes.csv')
                                                  ^
SyntaxError: unmatched ')'
[2025-03-09T18:03:31.361+0000] {processor.py:927} WARNING - No viable dags retrieved from /opt/airflow/dags/extra_dados_climaticos.py
[2025-03-09T18:03:31.390+0000] {processor.py:208} INFO - Processing /opt/airflow/dags/extra_dados_climaticos.py took 0.068 seconds
[2025-03-09T18:04:03.221+0000] {processor.py:186} INFO - Started process (PID=2442) to work on /opt/airflow/dags/extra_dados_climaticos.py
[2025-03-09T18:04:03.222+0000] {processor.py:914} INFO - Processing file /opt/airflow/dags/extra_dados_climaticos.py for tasks to queue
[2025-03-09T18:04:03.225+0000] {logging_mixin.py:190} INFO - [2025-03-09T18:04:03.224+0000] {dagbag.py:588} INFO - Filling up the DagBag from /opt/airflow/dags/extra_dados_climaticos.py
[2025-03-09T18:04:03.239+0000] {logging_mixin.py:190} INFO - [2025-03-09T18:04:03.238+0000] {dagbag.py:387} ERROR - Failed to import: /opt/airflow/dags/extra_dados_climaticos.py
Traceback (most recent call last):
  File "/home/airflow/.local/lib/python3.12/site-packages/airflow/models/dagbag.py", line 383, in parse
    loader.exec_module(new_module)
  File "<frozen importlib._bootstrap_external>", line 995, in exec_module
  File "<frozen importlib._bootstrap_external>", line 1133, in get_code
  File "<frozen importlib._bootstrap_external>", line 1063, in source_to_code
  File "<frozen importlib._bootstrap>", line 488, in _call_with_frames_removed
  File "/opt/airflow/dags/extra_dados_climaticos.py", line 41
    tarefa_1 >> tarefa_2ile_path + 'condicoes.csv')
                                                  ^
SyntaxError: unmatched ')'
[2025-03-09T18:04:03.240+0000] {processor.py:927} WARNING - No viable dags retrieved from /opt/airflow/dags/extra_dados_climaticos.py
[2025-03-09T18:04:03.261+0000] {processor.py:208} INFO - Processing /opt/airflow/dags/extra_dados_climaticos.py took 0.045 seconds
[2025-03-09T18:04:33.877+0000] {processor.py:186} INFO - Started process (PID=2494) to work on /opt/airflow/dags/extra_dados_climaticos.py
[2025-03-09T18:04:33.878+0000] {processor.py:914} INFO - Processing file /opt/airflow/dags/extra_dados_climaticos.py for tasks to queue
[2025-03-09T18:04:33.881+0000] {logging_mixin.py:190} INFO - [2025-03-09T18:04:33.880+0000] {dagbag.py:588} INFO - Filling up the DagBag from /opt/airflow/dags/extra_dados_climaticos.py
[2025-03-09T18:04:33.898+0000] {logging_mixin.py:190} INFO - [2025-03-09T18:04:33.897+0000] {dagbag.py:387} ERROR - Failed to import: /opt/airflow/dags/extra_dados_climaticos.py
Traceback (most recent call last):
  File "/home/airflow/.local/lib/python3.12/site-packages/airflow/models/dagbag.py", line 383, in parse
    loader.exec_module(new_module)
  File "<frozen importlib._bootstrap_external>", line 995, in exec_module
  File "<frozen importlib._bootstrap_external>", line 1133, in get_code
  File "<frozen importlib._bootstrap_external>", line 1063, in source_to_code
  File "<frozen importlib._bootstrap>", line 488, in _call_with_frames_removed
  File "/opt/airflow/dags/extra_dados_climaticos.py", line 41
    tarefa_1 >> tarefa_2ile_path + 'condicoes.csv')
                                                  ^
SyntaxError: unmatched ')'
[2025-03-09T18:04:33.899+0000] {processor.py:927} WARNING - No viable dags retrieved from /opt/airflow/dags/extra_dados_climaticos.py
[2025-03-09T18:04:33.941+0000] {processor.py:208} INFO - Processing /opt/airflow/dags/extra_dados_climaticos.py took 0.070 seconds
[2025-03-09T18:05:05.096+0000] {processor.py:186} INFO - Started process (PID=2557) to work on /opt/airflow/dags/extra_dados_climaticos.py
[2025-03-09T18:05:05.098+0000] {processor.py:914} INFO - Processing file /opt/airflow/dags/extra_dados_climaticos.py for tasks to queue
[2025-03-09T18:05:05.101+0000] {logging_mixin.py:190} INFO - [2025-03-09T18:05:05.101+0000] {dagbag.py:588} INFO - Filling up the DagBag from /opt/airflow/dags/extra_dados_climaticos.py
[2025-03-09T18:05:05.113+0000] {logging_mixin.py:190} INFO - [2025-03-09T18:05:05.112+0000] {dagbag.py:387} ERROR - Failed to import: /opt/airflow/dags/extra_dados_climaticos.py
Traceback (most recent call last):
  File "/home/airflow/.local/lib/python3.12/site-packages/airflow/models/dagbag.py", line 383, in parse
    loader.exec_module(new_module)
  File "<frozen importlib._bootstrap_external>", line 995, in exec_module
  File "<frozen importlib._bootstrap_external>", line 1133, in get_code
  File "<frozen importlib._bootstrap_external>", line 1063, in source_to_code
  File "<frozen importlib._bootstrap>", line 488, in _call_with_frames_removed
  File "/opt/airflow/dags/extra_dados_climaticos.py", line 41
    tarefa_1 >> tarefa_2ile_path + 'condicoes.csv')
                                                  ^
SyntaxError: unmatched ')'
[2025-03-09T18:05:05.114+0000] {processor.py:927} WARNING - No viable dags retrieved from /opt/airflow/dags/extra_dados_climaticos.py
[2025-03-09T18:05:05.139+0000] {processor.py:208} INFO - Processing /opt/airflow/dags/extra_dados_climaticos.py took 0.048 seconds
[2025-03-09T18:05:35.548+0000] {processor.py:186} INFO - Started process (PID=2621) to work on /opt/airflow/dags/extra_dados_climaticos.py
[2025-03-09T18:05:35.549+0000] {processor.py:914} INFO - Processing file /opt/airflow/dags/extra_dados_climaticos.py for tasks to queue
[2025-03-09T18:05:35.552+0000] {logging_mixin.py:190} INFO - [2025-03-09T18:05:35.552+0000] {dagbag.py:588} INFO - Filling up the DagBag from /opt/airflow/dags/extra_dados_climaticos.py
[2025-03-09T18:05:35.566+0000] {logging_mixin.py:190} INFO - [2025-03-09T18:05:35.564+0000] {dagbag.py:387} ERROR - Failed to import: /opt/airflow/dags/extra_dados_climaticos.py
Traceback (most recent call last):
  File "/home/airflow/.local/lib/python3.12/site-packages/airflow/models/dagbag.py", line 383, in parse
    loader.exec_module(new_module)
  File "<frozen importlib._bootstrap_external>", line 995, in exec_module
  File "<frozen importlib._bootstrap_external>", line 1133, in get_code
  File "<frozen importlib._bootstrap_external>", line 1063, in source_to_code
  File "<frozen importlib._bootstrap>", line 488, in _call_with_frames_removed
  File "/opt/airflow/dags/extra_dados_climaticos.py", line 41
    tarefa_1 >> tarefa_2ile_path + 'condicoes.csv')
                                                  ^
SyntaxError: unmatched ')'
[2025-03-09T18:05:35.567+0000] {processor.py:927} WARNING - No viable dags retrieved from /opt/airflow/dags/extra_dados_climaticos.py
[2025-03-09T18:05:35.591+0000] {processor.py:208} INFO - Processing /opt/airflow/dags/extra_dados_climaticos.py took 0.048 seconds
[2025-03-09T18:06:05.901+0000] {processor.py:186} INFO - Started process (PID=2685) to work on /opt/airflow/dags/extra_dados_climaticos.py
[2025-03-09T18:06:05.902+0000] {processor.py:914} INFO - Processing file /opt/airflow/dags/extra_dados_climaticos.py for tasks to queue
[2025-03-09T18:06:05.905+0000] {logging_mixin.py:190} INFO - [2025-03-09T18:06:05.904+0000] {dagbag.py:588} INFO - Filling up the DagBag from /opt/airflow/dags/extra_dados_climaticos.py
[2025-03-09T18:06:05.919+0000] {logging_mixin.py:190} INFO - [2025-03-09T18:06:05.917+0000] {dagbag.py:387} ERROR - Failed to import: /opt/airflow/dags/extra_dados_climaticos.py
Traceback (most recent call last):
  File "/home/airflow/.local/lib/python3.12/site-packages/airflow/models/dagbag.py", line 383, in parse
    loader.exec_module(new_module)
  File "<frozen importlib._bootstrap_external>", line 995, in exec_module
  File "<frozen importlib._bootstrap_external>", line 1133, in get_code
  File "<frozen importlib._bootstrap_external>", line 1063, in source_to_code
  File "<frozen importlib._bootstrap>", line 488, in _call_with_frames_removed
  File "/opt/airflow/dags/extra_dados_climaticos.py", line 41
    tarefa_1 >> tarefa_2ile_path + 'condicoes.csv')
                                                  ^
SyntaxError: unmatched ')'
[2025-03-09T18:06:05.921+0000] {processor.py:927} WARNING - No viable dags retrieved from /opt/airflow/dags/extra_dados_climaticos.py
[2025-03-09T18:06:05.942+0000] {processor.py:208} INFO - Processing /opt/airflow/dags/extra_dados_climaticos.py took 0.047 seconds
[2025-03-09T18:06:36.675+0000] {processor.py:186} INFO - Started process (PID=2739) to work on /opt/airflow/dags/extra_dados_climaticos.py
[2025-03-09T18:06:36.676+0000] {processor.py:914} INFO - Processing file /opt/airflow/dags/extra_dados_climaticos.py for tasks to queue
[2025-03-09T18:06:36.678+0000] {logging_mixin.py:190} INFO - [2025-03-09T18:06:36.677+0000] {dagbag.py:588} INFO - Filling up the DagBag from /opt/airflow/dags/extra_dados_climaticos.py
[2025-03-09T18:06:36.690+0000] {logging_mixin.py:190} INFO - [2025-03-09T18:06:36.689+0000] {dagbag.py:387} ERROR - Failed to import: /opt/airflow/dags/extra_dados_climaticos.py
Traceback (most recent call last):
  File "/home/airflow/.local/lib/python3.12/site-packages/airflow/models/dagbag.py", line 383, in parse
    loader.exec_module(new_module)
  File "<frozen importlib._bootstrap_external>", line 995, in exec_module
  File "<frozen importlib._bootstrap_external>", line 1133, in get_code
  File "<frozen importlib._bootstrap_external>", line 1063, in source_to_code
  File "<frozen importlib._bootstrap>", line 488, in _call_with_frames_removed
  File "/opt/airflow/dags/extra_dados_climaticos.py", line 41
    tarefa_1 >> tarefa_2ile_path + 'condicoes.csv')
                                                  ^
SyntaxError: unmatched ')'
[2025-03-09T18:06:36.691+0000] {processor.py:927} WARNING - No viable dags retrieved from /opt/airflow/dags/extra_dados_climaticos.py
[2025-03-09T18:06:36.711+0000] {processor.py:208} INFO - Processing /opt/airflow/dags/extra_dados_climaticos.py took 0.042 seconds
[2025-03-09T18:07:08.071+0000] {processor.py:186} INFO - Started process (PID=2805) to work on /opt/airflow/dags/extra_dados_climaticos.py
[2025-03-09T18:07:08.072+0000] {processor.py:914} INFO - Processing file /opt/airflow/dags/extra_dados_climaticos.py for tasks to queue
[2025-03-09T18:07:08.075+0000] {logging_mixin.py:190} INFO - [2025-03-09T18:07:08.074+0000] {dagbag.py:588} INFO - Filling up the DagBag from /opt/airflow/dags/extra_dados_climaticos.py
[2025-03-09T18:07:08.087+0000] {logging_mixin.py:190} INFO - [2025-03-09T18:07:08.087+0000] {dagbag.py:387} ERROR - Failed to import: /opt/airflow/dags/extra_dados_climaticos.py
Traceback (most recent call last):
  File "/home/airflow/.local/lib/python3.12/site-packages/airflow/models/dagbag.py", line 383, in parse
    loader.exec_module(new_module)
  File "<frozen importlib._bootstrap_external>", line 995, in exec_module
  File "<frozen importlib._bootstrap_external>", line 1133, in get_code
  File "<frozen importlib._bootstrap_external>", line 1063, in source_to_code
  File "<frozen importlib._bootstrap>", line 488, in _call_with_frames_removed
  File "/opt/airflow/dags/extra_dados_climaticos.py", line 41
    tarefa_1 >> tarefa_2ile_path + 'condicoes.csv')
                                                  ^
SyntaxError: unmatched ')'
[2025-03-09T18:07:08.088+0000] {processor.py:927} WARNING - No viable dags retrieved from /opt/airflow/dags/extra_dados_climaticos.py
[2025-03-09T18:07:08.108+0000] {processor.py:208} INFO - Processing /opt/airflow/dags/extra_dados_climaticos.py took 0.041 seconds
[2025-03-09T18:07:38.332+0000] {processor.py:186} INFO - Started process (PID=2863) to work on /opt/airflow/dags/extra_dados_climaticos.py
[2025-03-09T18:07:38.336+0000] {processor.py:914} INFO - Processing file /opt/airflow/dags/extra_dados_climaticos.py for tasks to queue
[2025-03-09T18:07:38.341+0000] {logging_mixin.py:190} INFO - [2025-03-09T18:07:38.341+0000] {dagbag.py:588} INFO - Filling up the DagBag from /opt/airflow/dags/extra_dados_climaticos.py
[2025-03-09T18:07:38.356+0000] {logging_mixin.py:190} INFO - [2025-03-09T18:07:38.355+0000] {dagbag.py:387} ERROR - Failed to import: /opt/airflow/dags/extra_dados_climaticos.py
Traceback (most recent call last):
  File "/home/airflow/.local/lib/python3.12/site-packages/airflow/models/dagbag.py", line 383, in parse
    loader.exec_module(new_module)
  File "<frozen importlib._bootstrap_external>", line 995, in exec_module
  File "<frozen importlib._bootstrap_external>", line 1133, in get_code
  File "<frozen importlib._bootstrap_external>", line 1063, in source_to_code
  File "<frozen importlib._bootstrap>", line 488, in _call_with_frames_removed
  File "/opt/airflow/dags/extra_dados_climaticos.py", line 41
    tarefa_1 >> tarefa_2ile_path + 'condicoes.csv')
                                                  ^
SyntaxError: unmatched ')'
[2025-03-09T18:07:38.357+0000] {processor.py:927} WARNING - No viable dags retrieved from /opt/airflow/dags/extra_dados_climaticos.py
[2025-03-09T18:07:38.384+0000] {processor.py:208} INFO - Processing /opt/airflow/dags/extra_dados_climaticos.py took 0.060 seconds
[2025-03-09T18:08:09.249+0000] {processor.py:186} INFO - Started process (PID=2927) to work on /opt/airflow/dags/extra_dados_climaticos.py
[2025-03-09T18:08:09.250+0000] {processor.py:914} INFO - Processing file /opt/airflow/dags/extra_dados_climaticos.py for tasks to queue
[2025-03-09T18:08:09.252+0000] {logging_mixin.py:190} INFO - [2025-03-09T18:08:09.252+0000] {dagbag.py:588} INFO - Filling up the DagBag from /opt/airflow/dags/extra_dados_climaticos.py
[2025-03-09T18:08:09.265+0000] {logging_mixin.py:190} INFO - [2025-03-09T18:08:09.264+0000] {dagbag.py:387} ERROR - Failed to import: /opt/airflow/dags/extra_dados_climaticos.py
Traceback (most recent call last):
  File "/home/airflow/.local/lib/python3.12/site-packages/airflow/models/dagbag.py", line 383, in parse
    loader.exec_module(new_module)
  File "<frozen importlib._bootstrap_external>", line 995, in exec_module
  File "<frozen importlib._bootstrap_external>", line 1133, in get_code
  File "<frozen importlib._bootstrap_external>", line 1063, in source_to_code
  File "<frozen importlib._bootstrap>", line 488, in _call_with_frames_removed
  File "/opt/airflow/dags/extra_dados_climaticos.py", line 41
    tarefa_1 >> tarefa_2ile_path + 'condicoes.csv')
                                                  ^
SyntaxError: unmatched ')'
[2025-03-09T18:08:09.266+0000] {processor.py:927} WARNING - No viable dags retrieved from /opt/airflow/dags/extra_dados_climaticos.py
[2025-03-09T18:08:09.287+0000] {processor.py:208} INFO - Processing /opt/airflow/dags/extra_dados_climaticos.py took 0.044 seconds
[2025-03-09T18:08:39.602+0000] {processor.py:186} INFO - Started process (PID=2994) to work on /opt/airflow/dags/extra_dados_climaticos.py
[2025-03-09T18:08:39.603+0000] {processor.py:914} INFO - Processing file /opt/airflow/dags/extra_dados_climaticos.py for tasks to queue
[2025-03-09T18:08:39.606+0000] {logging_mixin.py:190} INFO - [2025-03-09T18:08:39.605+0000] {dagbag.py:588} INFO - Filling up the DagBag from /opt/airflow/dags/extra_dados_climaticos.py
[2025-03-09T18:08:39.623+0000] {logging_mixin.py:190} INFO - [2025-03-09T18:08:39.622+0000] {dagbag.py:387} ERROR - Failed to import: /opt/airflow/dags/extra_dados_climaticos.py
Traceback (most recent call last):
  File "/home/airflow/.local/lib/python3.12/site-packages/airflow/models/dagbag.py", line 383, in parse
    loader.exec_module(new_module)
  File "<frozen importlib._bootstrap_external>", line 995, in exec_module
  File "<frozen importlib._bootstrap_external>", line 1133, in get_code
  File "<frozen importlib._bootstrap_external>", line 1063, in source_to_code
  File "<frozen importlib._bootstrap>", line 488, in _call_with_frames_removed
  File "/opt/airflow/dags/extra_dados_climaticos.py", line 41
    tarefa_1 >> tarefa_2ile_path + 'condicoes.csv')
                                                  ^
SyntaxError: unmatched ')'
[2025-03-09T18:08:39.624+0000] {processor.py:927} WARNING - No viable dags retrieved from /opt/airflow/dags/extra_dados_climaticos.py
[2025-03-09T18:08:39.651+0000] {processor.py:208} INFO - Processing /opt/airflow/dags/extra_dados_climaticos.py took 0.058 seconds
[2025-03-09T18:09:10.047+0000] {processor.py:186} INFO - Started process (PID=3060) to work on /opt/airflow/dags/extra_dados_climaticos.py
[2025-03-09T18:09:10.049+0000] {processor.py:914} INFO - Processing file /opt/airflow/dags/extra_dados_climaticos.py for tasks to queue
[2025-03-09T18:09:10.057+0000] {logging_mixin.py:190} INFO - [2025-03-09T18:09:10.056+0000] {dagbag.py:588} INFO - Filling up the DagBag from /opt/airflow/dags/extra_dados_climaticos.py
[2025-03-09T18:09:10.085+0000] {logging_mixin.py:190} INFO - [2025-03-09T18:09:10.083+0000] {dagbag.py:387} ERROR - Failed to import: /opt/airflow/dags/extra_dados_climaticos.py
Traceback (most recent call last):
  File "/home/airflow/.local/lib/python3.12/site-packages/airflow/models/dagbag.py", line 383, in parse
    loader.exec_module(new_module)
  File "<frozen importlib._bootstrap_external>", line 995, in exec_module
  File "<frozen importlib._bootstrap_external>", line 1133, in get_code
  File "<frozen importlib._bootstrap_external>", line 1063, in source_to_code
  File "<frozen importlib._bootstrap>", line 488, in _call_with_frames_removed
  File "/opt/airflow/dags/extra_dados_climaticos.py", line 41
    tarefa_1 >> tarefa_2ile_path + 'condicoes.csv')
                                                  ^
SyntaxError: unmatched ')'
[2025-03-09T18:09:10.087+0000] {processor.py:927} WARNING - No viable dags retrieved from /opt/airflow/dags/extra_dados_climaticos.py
[2025-03-09T18:09:10.124+0000] {processor.py:208} INFO - Processing /opt/airflow/dags/extra_dados_climaticos.py took 0.090 seconds
[2025-03-09T18:09:40.343+0000] {processor.py:186} INFO - Started process (PID=3126) to work on /opt/airflow/dags/extra_dados_climaticos.py
[2025-03-09T18:09:40.344+0000] {processor.py:914} INFO - Processing file /opt/airflow/dags/extra_dados_climaticos.py for tasks to queue
[2025-03-09T18:09:40.346+0000] {logging_mixin.py:190} INFO - [2025-03-09T18:09:40.346+0000] {dagbag.py:588} INFO - Filling up the DagBag from /opt/airflow/dags/extra_dados_climaticos.py
[2025-03-09T18:09:40.357+0000] {logging_mixin.py:190} INFO - [2025-03-09T18:09:40.357+0000] {dagbag.py:387} ERROR - Failed to import: /opt/airflow/dags/extra_dados_climaticos.py
Traceback (most recent call last):
  File "/home/airflow/.local/lib/python3.12/site-packages/airflow/models/dagbag.py", line 383, in parse
    loader.exec_module(new_module)
  File "<frozen importlib._bootstrap_external>", line 995, in exec_module
  File "<frozen importlib._bootstrap_external>", line 1133, in get_code
  File "<frozen importlib._bootstrap_external>", line 1063, in source_to_code
  File "<frozen importlib._bootstrap>", line 488, in _call_with_frames_removed
  File "/opt/airflow/dags/extra_dados_climaticos.py", line 41
    tarefa_1 >> tarefa_2ile_path + 'condicoes.csv')
                                                  ^
SyntaxError: unmatched ')'
[2025-03-09T18:09:40.358+0000] {processor.py:927} WARNING - No viable dags retrieved from /opt/airflow/dags/extra_dados_climaticos.py
[2025-03-09T18:09:40.380+0000] {processor.py:208} INFO - Processing /opt/airflow/dags/extra_dados_climaticos.py took 0.043 seconds
[2025-03-09T18:10:10.939+0000] {processor.py:186} INFO - Started process (PID=3192) to work on /opt/airflow/dags/extra_dados_climaticos.py
[2025-03-09T18:10:10.940+0000] {processor.py:914} INFO - Processing file /opt/airflow/dags/extra_dados_climaticos.py for tasks to queue
[2025-03-09T18:10:10.945+0000] {logging_mixin.py:190} INFO - [2025-03-09T18:10:10.944+0000] {dagbag.py:588} INFO - Filling up the DagBag from /opt/airflow/dags/extra_dados_climaticos.py
[2025-03-09T18:10:10.958+0000] {logging_mixin.py:190} INFO - [2025-03-09T18:10:10.957+0000] {dagbag.py:387} ERROR - Failed to import: /opt/airflow/dags/extra_dados_climaticos.py
Traceback (most recent call last):
  File "/home/airflow/.local/lib/python3.12/site-packages/airflow/models/dagbag.py", line 383, in parse
    loader.exec_module(new_module)
  File "<frozen importlib._bootstrap_external>", line 995, in exec_module
  File "<frozen importlib._bootstrap_external>", line 1133, in get_code
  File "<frozen importlib._bootstrap_external>", line 1063, in source_to_code
  File "<frozen importlib._bootstrap>", line 488, in _call_with_frames_removed
  File "/opt/airflow/dags/extra_dados_climaticos.py", line 41
    tarefa_1 >> tarefa_2ile_path + 'condicoes.csv')
                                                  ^
SyntaxError: unmatched ')'
[2025-03-09T18:10:10.960+0000] {processor.py:927} WARNING - No viable dags retrieved from /opt/airflow/dags/extra_dados_climaticos.py
[2025-03-09T18:10:10.987+0000] {processor.py:208} INFO - Processing /opt/airflow/dags/extra_dados_climaticos.py took 0.053 seconds
